2021-08-13 15:56:40,414 [INFO ]  Starting Rasa server on http://localhost:5005
2021-08-13 15:56:40,424 [INFO ]  Loading model models/20210813-092543.tar.gz...
2021-08-13 15:56:44,989 [INFO ]  Loading model models/20210813-092543.tar.gz...
2021-08-13 15:57:38,637 [INFO ]  Rasa server is up and running.
2021-08-13 15:57:55,853 [ERROR]  Exception occurred while handling uri: 'http://localhost:5005/socket.io/?EIO=3&transport=polling&t=Nj01GI4'
Traceback (most recent call last):
  File "/Users/bg5fxp_jf/rasa_project_OIcoach/venv/lib/python3.7/site-packages/sanic/app.py", line 931, in handle_request
    response = await response
  File "/Users/bg5fxp_jf/rasa_project_OIcoach/venv/lib/python3.7/site-packages/engineio/asyncio_server.py", line 306, in handle_request
    r['response'], environ)
  File "/Users/bg5fxp_jf/rasa_project_OIcoach/venv/lib/python3.7/site-packages/engineio/async_drivers/sanic.py", line 104, in make_response
    status=int(status.split()[0]), headers=headers_dict)
TypeError: __init__() got an unexpected keyword argument 'body_bytes'
2021-08-13 15:57:56,570 [ERROR]  Exception occurred while handling uri: 'http://localhost:5005/socket.io/?EIO=3&transport=polling&t=Nj01GTN'
Traceback (most recent call last):
  File "/Users/bg5fxp_jf/rasa_project_OIcoach/venv/lib/python3.7/site-packages/sanic/app.py", line 931, in handle_request
    response = await response
  File "/Users/bg5fxp_jf/rasa_project_OIcoach/venv/lib/python3.7/site-packages/engineio/asyncio_server.py", line 306, in handle_request
    r['response'], environ)
  File "/Users/bg5fxp_jf/rasa_project_OIcoach/venv/lib/python3.7/site-packages/engineio/async_drivers/sanic.py", line 104, in make_response
    status=int(status.split()[0]), headers=headers_dict)
TypeError: __init__() got an unexpected keyword argument 'body_bytes'
2021-08-13 15:57:57,969 [ERROR]  Exception occurred while handling uri: 'http://localhost:5005/socket.io/?EIO=3&transport=polling&t=Nj01GpE'
Traceback (most recent call last):
  File "/Users/bg5fxp_jf/rasa_project_OIcoach/venv/lib/python3.7/site-packages/sanic/app.py", line 931, in handle_request
    response = await response
  File "/Users/bg5fxp_jf/rasa_project_OIcoach/venv/lib/python3.7/site-packages/engineio/asyncio_server.py", line 306, in handle_request
    r['response'], environ)
  File "/Users/bg5fxp_jf/rasa_project_OIcoach/venv/lib/python3.7/site-packages/engineio/async_drivers/sanic.py", line 104, in make_response
    status=int(status.split()[0]), headers=headers_dict)
TypeError: __init__() got an unexpected keyword argument 'body_bytes'
2021-08-13 15:57:58,784 [ERROR]  Exception occurred while handling uri: 'http://localhost:5005/socket.io/?EIO=3&transport=polling&t=Nj01G_z'
Traceback (most recent call last):
  File "/Users/bg5fxp_jf/rasa_project_OIcoach/venv/lib/python3.7/site-packages/sanic/app.py", line 931, in handle_request
    response = await response
  File "/Users/bg5fxp_jf/rasa_project_OIcoach/venv/lib/python3.7/site-packages/engineio/asyncio_server.py", line 306, in handle_request
    r['response'], environ)
  File "/Users/bg5fxp_jf/rasa_project_OIcoach/venv/lib/python3.7/site-packages/engineio/async_drivers/sanic.py", line 104, in make_response
    status=int(status.split()[0]), headers=headers_dict)
TypeError: __init__() got an unexpected keyword argument 'body_bytes'
2021-08-13 15:57:59,884 [ERROR]  Exception occurred while handling uri: 'http://localhost:5005/socket.io/?EIO=3&transport=polling&t=Nj01HH9'
Traceback (most recent call last):
  File "/Users/bg5fxp_jf/rasa_project_OIcoach/venv/lib/python3.7/site-packages/sanic/app.py", line 931, in handle_request
    response = await response
  File "/Users/bg5fxp_jf/rasa_project_OIcoach/venv/lib/python3.7/site-packages/engineio/asyncio_server.py", line 306, in handle_request
    r['response'], environ)
  File "/Users/bg5fxp_jf/rasa_project_OIcoach/venv/lib/python3.7/site-packages/engineio/async_drivers/sanic.py", line 104, in make_response
    status=int(status.split()[0]), headers=headers_dict)
TypeError: __init__() got an unexpected keyword argument 'body_bytes'
2021-08-13 15:58:01,244 [ERROR]  Exception occurred while handling uri: 'http://localhost:5005/socket.io/?EIO=3&transport=polling&t=Nj01HcO'
Traceback (most recent call last):
  File "/Users/bg5fxp_jf/rasa_project_OIcoach/venv/lib/python3.7/site-packages/sanic/app.py", line 931, in handle_request
    response = await response
  File "/Users/bg5fxp_jf/rasa_project_OIcoach/venv/lib/python3.7/site-packages/engineio/asyncio_server.py", line 306, in handle_request
    r['response'], environ)
  File "/Users/bg5fxp_jf/rasa_project_OIcoach/venv/lib/python3.7/site-packages/engineio/async_drivers/sanic.py", line 104, in make_response
    status=int(status.split()[0]), headers=headers_dict)
TypeError: __init__() got an unexpected keyword argument 'body_bytes'
2021-08-13 16:00:52,589 [ERROR]  Task was destroyed but it is pending!
task: <Task pending coro=<AsyncServer._service_task() running at /Users/bg5fxp_jf/rasa_project_OIcoach/venv/lib/python3.7/site-packages/engineio/asyncio_server.py:454> wait_for=<Future pending cb=[<TaskWakeupMethWrapper object at 0x7fd1c3963610>()]>>
